Workbook
Name FactionList: Factions[Faction]
Name RULESOF: _xlfn.LAMBDA(_xlpm.fac,_xlfn.LET(_xlpm.k,_xlfn.XMATCH(TRIM(_xlpm.fac),Factions[Faction]),IFERROR(_xlfn.TAKE(_xlfn.CHOOSECOLS(FACTIONBLOCK(_xlpm.k),_xlfn.SEQUENCE(1,4,38)),27),{"","","",""})))
Name STRATSOF: _xlfn.LAMBDA(_xlpm.fac,_xlfn.LET(_xlpm.k,_xlfn.XMATCH(TRIM(_xlpm.fac),Factions[Faction]),IFERROR(_xlfn.TAKE(_xlfn.CHOOSECOLS(FACTIONBLOCK(_xlpm.k),_xlfn.SEQUENCE(1,6,43)),27),{"","","","","",""})))

Sheet How To Use
B2: Combat 40k Cheat Sheet – How To Use This Workbook
B3: This workbook works out the average damage a unit will do to an enemy unit in Warhammer 40,000 (11th edition), taking weapon keywords, faction rules, stratagems and battle conditions into account. You enter your units once on a faction tab, then pick attacker and target on the Sim tabs.
B5: 1. What each tab is for
B6: Sim-Shooting | C6: Simulates your unit's ranged weapons shooting at a target.
B7: Sim-Fighting | C7: Simulates your unit's melee weapons fighting a target.
B8: Roster | C8: Lists your whole army and the opponent (real units or generic profiles) with shared battle conditions and army-wide rules. Feeds the army-level results.
B9: Results | C9: Army-wide analysis built from the Roster tab: kill grid, heat maps, gaps, role spider chart, points efficiency and reverse durability.
B10: Faction tabs | C10: DeathGuard, Space Marines, Drukhari, Daemons, T'Au, Imperial Guard, Sisters of Battle, Thousand Sons. Each holds that faction's units, weapons, faction rules and stratagems. Every unit here can be an attacker or a target.
B11: Keywords | C11: Reference list of every 11th edition keyword and the core stratagems, plus the Modifier Format Guide that explains how to write keywords so the simulator can read them.
B13: 2. Adding a unit (on a faction tab)
B14: Step 1 – Unit table (B:R) | C14: In column B type the unit's Name. In C:H enter its stats: T (Toughness), W (Wounds), Sv (Save), InSv (Invulnerable save, or - if none), FNP (Feel No Pain, or -), and Modifiers (unit keywords, e.g. Infantry, Stealth). In I:P add the rest of the datasheet: M (Move), OC, Ld (Leadership), Points, Models (models in the unit), Keywords (e.g. Infantry, Character, Vehicle), Leader (units this character can lead) and Abilities. Give every unit a unique name within its faction tab.
B15: Step 2 – List its weapons | C15: In column Q list each weapon the unit carries, one per row under its name. In column R pick Ranged or Melee from the dropdown. This decides whether it appears on Sim-Shooting or Sim-Fighting. If a unit has several weapons, merge its Name cell down across those rows or leave the rows below the name blank. In column S (Qty) enter how many of that weapon the unit has (blank = 1); enter 0 for alternative profiles such as frag/krak so they aren't added together.
B16: Step 3 – Weapon profiles | C16: Add the weapon's stats to the Ranged Weapons table (U:AA) or the Melee Weapons table (AD:AJ): Weapon name (must match column Q exactly), A, BS/WS, S, AP, D and Modifier. Random values such as D3 or D6 are fine.
B17: Tip | C17: A weapon profile only needs to be entered once per faction tab, even if several units carry it.
B19: 3. Writing keywords (Modifier columns)
B20: Use exact names | C20: Write keywords exactly as they appear in the Keywords tab, e.g. Lethal Hits not Lethal.
B21: Separate with commas | C21: Blast, Lethal Hits
B22: Space before numbers | C22: Melta 2, Rapid Fire 1, Sustained Hits 1
B23: Anti and Feel No Pain | C23: Anti-Infantry 2+ and Feel No Pain 5+
B24: Stat changes | C24: Hit Modifier +1, Wound Modifier -1, AP Modifier -1, Damage Modifier -1, Attacks Modifier +1, Strength Modifier +1, BS Modifier -1 / WS Modifier -1 (minus improves), Toughness Modifier +1, Save Modifier +1, Critical Hits 5+, Critical Wounds 5+, Reroll Hits, Reroll Wounds, Reroll Hits 1 (re-roll 1s only). Full list and examples on the Keywords tab.
B25: Unit keywords | C25: Target keywords used by Anti go in the unit's Modifiers, e.g. Infantry, Feel No Pain 5+.
B27: 4. Running a simulation (Sim-Shooting / Sim-Fighting)
B28: Step 1 – Pick the attacker | C28: B3: choose the attacking faction. B4: choose the attacking unit. Its weapons fill in automatically from row 6 down.
B29: Step 2 – Pick the target | C29: I4: choose the target unit from any faction tab. Targets are listed as Unit (Faction), e.g. Intercessor (Space Marines), so units with the same name in different factions don't get mixed up. Its stats appear in I6:N6.
B30: Step 3 – Set battle conditions | C30: Use the yellow Yes/No switches in rows 2–3. Shooting: Within Half Range (Melta, Rapid Fire), Attacker Stationary (Heavy), Target in Cover, Target Models (Blast), Attacker Damaged. Fighting: Charged This Turn (Lance), Target Models (Cleave), Attacker Damaged.
B31: Step 4 – Choose weapons | C31: Tick the Use box in column A next to each weapon you want included. Untick weapons the unit isn't firing or fighting with. In the Qty column (B) next to each tick box, enter how many of that weapon are being used (default 1) – attacks scale by this number.
B32: Step 5 – Rules and stratagems | C32: Scroll down to the Attacker panel (from row 32) and Target panel (from row 50). Tick any faction rules or stratagems that are active. You can tick as many as you like; their effects stack. The Attacker Effects and Target Effects cells in the top row show everything currently active.
B33: Step 6 – Read the results | C33: Each weapon row shows Attacks, Hits, Wounds, Mortal Wounds, Unsaved wounds, Damage and Models Killed. The totals for all ticked weapons are in P2:Q3 (Total Damage and Total Models Killed).
B35: 5. Adding faction rules and stratagems
B36: Faction Rules (AM:AP) | C36: On a faction tab, enter the Rule name, pick Applies To (Attacker = helps that faction's units attack, Target = helps them when being attacked), pick the Phase (Shooting, Fighting or Both), and write its effect in Modifier using the keyword format, e.g. Hit Modifier +1, Lethal Hits.
B37: Faction Stratagems (AR:AW) | C37: Same idea as Faction Rules, with a CP cost and notes column.
B38: Core stratagems | C38: Generic stratagems everyone can use are on the Keywords tab (Core Stratagems table) and appear on every faction's Sim panels automatically.
B40: 6. Army Roster (Roster tab)
B41: Step 1 – Your army | C41: Pick My Faction (C5), then in the My Army table tick Use and choose each unit. Leave Models blank to use the datasheet count, or enter a different unit size – damage and points scale by Models ÷ Datasheet Models.
B42: Step 2 – Opponent | C42: Set Opponent Mode (C12). Real roster: pick the Opponent Faction (C13), then tick and choose enemy units from that faction in the Real Roster table; stats fill in automatically and you can override Models or add Extra Mods. Generic profiles: tick and edit the benchmark stat lines and their weights.
B43: Step 3 – Conditions & army rules | C43: Phase (Shooting / Fighting / Both) and the Yes/No switches in C7:C11 apply to every unit. Tick army-wide rules and stratagems in the panel at N4 – they apply to every unit in the matching phase.
B44: Helper columns | C44: Grouped columns Z:BB hold the lists and calculation inputs used by the results tabs. Click + above the columns to expand; don't edit them.
B45: Step 4 – Read the Results tab | C45: Results shows: an Army Summary; 1) Kill Grid (expected models killed per unit vs each target, with army totals, one-turn wipe check and best unit); 2) % destroyed heat map with weighted average and % per 100 pts; 3) Gaps list; 4) Role Scores and spider chart (edit the blue benchmark profiles); 5) Toughness/Save coverage heat map; 6) Reverse Durability – how much of each of your units the opponent destroys (Real roster mode only). Phase Both = shoot then fight, kills added together. Charts: the Points Efficiency bar chart (next to Gaps) and the Role Profile spider chart. Heat maps run red (weak) to green (strong). On the Roster, the opponent section not in use is greyed out. Blue cells everywhere are inputs.
B47: 7. Good to know
B48: Averages, not dice | C48: Results are the average expected outcome, not a random roll. Random values use their average (D3 = 2, D6 = 3.5).
...

Sheet Keywords
B2: Keyword | C2: Category | D2: Applies To | E2: Format | F2: Rule Summary | G2: Sim Step | H2: Modelled in Sim? | I2: Rule Ref | K2: Modifier Format Guide | N2: Faction
B3: Anti | C3: Weapon | D3: Both | E3: Anti-X Y+ | F3: Unmodified wound roll of Y+ is a Critical Wound vs targets with keyword X. | G3: Wound | H3: Yes | I3: 24.03 | K3: Rule | L3: Example | N3: DeathGuard
B4: Assault | C4: Weapon | D4: Ranged | E4: Assault | F4: Unit can use Assault Shooting (shoot after Advancing). | G4: None | H4: No | I4: 24.04 | K4: Use the exact name from the Keyword column | L4: Lethal Hits (not Lethal) | N4: Space Marines
B5: Blast | C5: Weapon | D5: Ranged | E5: Blast / Blast X | F5: +1 (or +X) attack dice per 5 models in the target unit (round down). | G5: Attacks | H5: Yes | I5: 24.05 | K5: Separate multiple keywords with a comma and space | L5: Blast, Lethal Hits | N5: Drukhari
B6: Cleave | C6: Weapon | D6: Melee | E6: Cleave X | F6: +X attack dice per 5 models in the target unit, if all attacks target one unit. | G6: Attacks | H6: Yes | I6: 24.06 | K6: Put a space before any value | L6: Melta 2, Rapid Fire 1, Sustained Hits 1 | N6: Daemons
B7: Close-Quarters | C7: Weapon | D7: Ranged | E7: Close-Quarters | F7: Unit can use Close-Quarters Shooting while engaged; limits weapon choice with other shooting types. | G7: None | H7: No | I7: 24.07 | K7: Anti: target keyword after a hyphen, then a space and the roll needed with + | L7: Anti-Infantry 2+ | N7: T'Au
B8: Devastating Wounds | C8: Weapon | D8: Both | E8: Devastating Wounds | F8: A Critical Wound ends the attack sequence and inflicts mortal wounds equal to the weapon's D. | G8: Save | H8: Yes | I8: 24.10 | K8: Feel No Pain (unit Modifiers): space, then roll needed with + | L8: Feel No Pain 5+ | N8: Imperial Guard
B9: Extra Attacks | C9: Weapon | D9: Melee | E9: Extra Attacks | F9: These weapons are used in addition to one other melee weapon. | G9: None | H9: No | I9: 24.11 | K9: Keywords with no value are written on their own | L9: Torrent, Heavy, Twin-Linked | N9: Sisters of Battle
B10: Hazardous | C10: Weapon | D10: Both | E10: Hazardous | F10: After attacking, make one hazard roll per Hazardous weapon selected. | G10: None | H10: No | I10: 24.15 | K10: Stat modifiers: name, space, then signed number (they stack) | L10: Hit Modifier +1, AP Modifier -1 | N10: Thousand Sons
B11: Heavy | C11: Weapon | D11: Ranged | E11: Heavy | F11: +1 to hit if unengaged, not set up this turn and no model moved more than 3". | G11: Hit | H11: Yes | I11: 24.16 | K11: Rerolls: full, or add 1 for re-rolling 1s only | L11: Reroll Hits, Reroll Wounds 1
B12: Ignores Cover | C12: Weapon | D12: Ranged | E12: Ignores Cover | F12: Target cannot gain the benefit of cover, so the attacker's BS is not worsened. | G12: Hit | H12: Yes | I12: 24.18 | K12: BS/WS and AP use the characteristic's own direction: -1 is better | L12: BS Modifier -1 (3+ to 2+), AP Modifier -1 (-1 to -2)
B13: Indirect Fire | C13: Weapon | D13: Ranged | E13: Indirect Fire | F13: Unit can use Indirect Shooting (no line of sight needed). | G13: None | H13: No | I13: 24.19 | K13: Critical Hits/Wounds: roll needed with + | L13: Critical Hits 5+, Critical Wounds 5+
B14: Lance | C14: Weapon | D14: Both | E14: Lance | F14: +1 to wound if the attacking unit charged this turn. | G14: Wound | H14: Yes | I14: 24.21 | K14: If the same keyword appears twice, the best value is used | L14: Sustained Hits 1 + Sustained Hits 2 = Sustained Hits 2
B15: Lethal Hits | C15: Weapon | D15: Both | E15: Lethal Hits | F15: A Critical Hit can automatically wound (no wound roll). | G15: Hit | H15: Yes | I15: 24.23
B16: Melta | C16: Weapon | D16: Ranged | E16: Melta X | F16: +X to D if the target is within half range. | G16: Damage | H16: Yes | I16: 24.25
B17: One Shot | C17: Weapon | D17: Both | E17: One Shot | F17: Weapon can only be used once per battle. | G17: None | H17: No | I17: 24.26
B18: Pistol | C18: Weapon | D18: Ranged | E18: Pistol | F18: Identical to Close-Quarters for all rules purposes (being phased out). | G18: None | H18: No | I18: 24.27
B19: Precision | C19: Weapon | D19: Both | E19: Precision | F19: Attacks can be allocated to a visible Character in the target unit first. | G19: None | H19: No | I19: 24.28
B20: Psychic | C20: Weapon | D20: Both | E20: Psychic | F20: Can ignore modifiers to BS/WS (including cover) and negative modifiers to the hit roll; counts as a psychic attack. | G20: Hit | H20: Yes | I20: 24.29
B21: Rapid Fire | C21: Weapon | D21: Ranged | E21: Rapid Fire X | F21: +X attack dice if the target is within half range. | G21: Attacks | H21: Yes | I21: 24.30
B22: Sustained Hits | C22: Weapon | D22: Both | E22: Sustained Hits X | F22: A Critical Hit scores X additional hits. | G22: Hit | H22: Yes | I22: 24.36
B23: Torrent | C23: Weapon | D23: Ranged | E23: Torrent | F23: Attacks automatically hit. Cannot also have Indirect Fire or Precision. | G23: Hit | H23: Yes | I23: 24.37
B24: Twin-Linked | C24: Weapon | D24: Both | E24: Twin-Linked | F24: Can re-roll the wound roll. | G24: Wound | H24: Yes | I24: 24.38
B25: Damaged | C25: Core | D25: Unit | E25: Damaged X | F25: While remaining wounds are X or fewer, the model's attacks get -1 to hit. | G25: Hit | H25: Yes | I25: 24.39
B26: Deadly Demise | C26: Core | D26: Unit | E26: Deadly Demise X | F26: When destroyed, on a 6 each unit within 6" suffers X mortal wounds. | G26: None | H26: No | I26: 24.08
... B53: Critical Wounds | C53: Stat | D53: Both | E53: Critical Wounds X+ | F53: Unmodified wound rolls of X+ are Critical Wounds (and always wound). Combines with Anti; lowest value applies. | G53: Wound | H53: Yes | I53: 05.02
B62: Core Stratagems
B63: Stratagem | C63: CP | D63: Applies To | E63: Phase | F63: Modifier | G63: Notes
B64: Command Re-roll | C64: 1 | D64: Attacker | E64: Both | G64: Re-roll one hit, wound, damage or attacks roll. A single re-roll isn't modelled in the averages.
B65: Epic Challenge | C65: 1 | D65: Attacker | E65: Fighting | F65: Precision | G65: One Character's melee weapons gain Precision. No effect on damage maths.
B66: Explosives | C66: 1 | D66: Attacker | E66: Shooting | G66: Separate grenade attack sequence; not modelled.
B67: Fire Overwatch | C67: 1 | D67: Attacker | E67: Shooting | F67: Snap Shooting | G67: Shoot using snap shooting: hits only on unmodified 6s, or 4+ if the unit remained stationary. No hit re-rolls.
B68: Counteroffensive | C68: 2 | D68: Attacker | E68: Fighting | G68: Unit gains Fights First. No effect on damage maths.
B69: Smokescreen | C69: 1 | D69: Target | E69: Shooting | F69: Stealth | G69: SMOKE unit gains the benefit of cover against ranged attacks.
B70: Insane Bravery | C70: 1 | D70: Attacker | E70: Other | G70: Auto-pass a battle-shock roll.
B71: Crushing Impact | C71: 1 | D71: Attacker | E71: Other | G71: Charge-phase mortal wounds from a Monster/Vehicle; not modelled.
B72: Rapid Ingress | C72: 1 | D72: Attacker | E72: Other | G72: Ingress move at end of opponent's Movement phase.
B73: Heroic Intervention | C73: 1 | D73: Attacker | E73: Other | G73: Charge at end of opponent's Charge phase.

Sheet Sim-Shooting
C2: Faction | E2: Within Half Range? | F2: Attacker Stationary? | G2: Target in Cover? | H2: Target Models | I2: Attacker Damaged? | J2: Attacker Effects | L2: Target Effects | P2: Total Damage | Q2: Total Models Killed | R2: Weapons in Use | S2: Check | AA2: Target FNP | AB2: Target Stealth | AC2: Attacker Rule Mods | AD2: Target Rule Mods | AE2: Target Faction | AF2: Target T Mod | AG2: Target Save Mod | AH2: Target Dmg Mod | AI2: Target Hit Mod | AJ2: Target Wound Mod | AK2: Target AP Mod
C3: DeathGuard | E3: Yes | F3: Yes | G3: No | H3: 10 | I3: No | J3: =IF($AC$3="","None ticked",$AC$3) -> None ticked | L3: =IF($AD$3="","None ticked",$AD$3) -> None ticked | P3: =SUM(W6:W30) -> 3.6666667 | Q3: =MIN($H$3,SUM(X6:X30)) -> 0.20842411 | R3: {=SUMPRODUCT(($C$6:$C$30<>"")*($A$6:$A$30=TRUE))&" of "&COUNTIF($C$6:$C$30,"?*")} -> 7 of 7 | S3: {=_xlfn.LET(_xlpm.nw,IFERROR(IF(INDEX(_xlfn.ANCHORARRAY($C$6),1)="",0,ROWS(_xlfn.ANCHORARRAY($C$6))),0),_xlpm.un,_xlfn._xlws.FILTER($C$6:$C$30,($C$6:$C$30<>"")*($A$6:$A$30=FALSE),""),_xlpm.ao,IFERROR(ROWS(OPTIONS($C$3,"Attacker","Shooting")),0),_xlpm.to,IFERROR(ROWS(OPTIONS($AE$3,"Target","Shooting")),0),_xlpm.bad,SUMPRODUCT(($A$34:$A$48=TRUE)*($C$34:$C$48=""))+SUMPRODUCT(($A$52:$A$66=TRUE)*($C$52:$C$66="")),_xlpm.w,_xlfn.TEXTJOIN(" | ",TRUE,IF($AE$3="","Target not found - pick a target in I4",""),IF(AND(_xlpm.nw>0,$AE$3<>"",OR(N($J$6)<=0,N($K$6)<=0,NOT(ISNUMBER($L$6)))),"Target is missing T, W or Sv",""),IF(_xlpm.nw>25,"Unit has "&_xlpm.nw&" weapons - only the first 25 are shown",""),IF(_xlpm.ao>15,"Attacker has "&_xlpm.ao&" rules/stratagems - only 15 shown",""),IF(_xlpm.to>15,"Target has "&_xlpm.to&" rules/stratagems - only 15 shown",""),IF(_xlpm.bad>0,_xlpm.bad&" ticked rule/stratagem row(s) are empty - untick them",""),IF(INDEX(_xlpm.un,1)<>"","Unticked: "&_xlfn.TEXTJOIN(", ",TRUE,_xlpm.un),"")),IF(_xlpm.w="","OK - after changing unit, target or faction, re-check your ticks",_xlpm.w))} -> OK - after changing unit, target or faction, re-check your ticks | AA3: {=_xlfn.LET(_xlpm.a,$N$6,_xlpm.b,KWMIN(($O$6&", "&$AD$3),"Feel No Pain"),MIN(IF(AND(ISNUMBER(_xlpm.a),_xlpm.a>=2,_xlpm.a<=6),_xlpm.a,7),IF(ISNUMBER(_xlpm.b),_xlpm.b,7)))} -> 7 | AB3: {=KW(($O$6&", "&$AD$3),"Stealth")=TRUE} -> FALSE | AC3: {=_xlfn.TEXTJOIN(", ",TRUE,_xlfn._xlws.FILTER($E$34:$E$48,($A$34:$A$48=TRUE)*($C$34:$C$48<>""),""))} | AD3: {=_xlfn.TEXTJOIN(", ",TRUE,_xlfn._xlws.FILTER($E$52:$E$66,($A$52:$A$66=TRUE)*($C$52:$C$66<>""),""))} | AE3: =IFERROR(_xlfn.TEXTBEFORE(_xlfn.TEXTAFTER($J$4," (",-1),")",-1),"") -> Imperial Guard | AF3: {=KWSUM(($O$6&", "&$AD$3),"Toughness Modifier")} -> 0 | AG3: {=KWSUM(($O$6&", "&$AD$3),"Save Modifier")} -> 0 | AH3: {=KWSUM(($O$6&", "&$AD$3),"Damage Modifier")} -> 0 | AI3: {=KWSUM(($O$6&", "&$AD$3),"Hit Modifier")} -> 0 | AJ3: {=KWSUM(($O$6&", "&$AD$3),"Wound Modifier")} -> 0 | AK3: {=KWSUM(($O$6&", "&$AD$3),"AP Modifier")} -> 0
C4: Plague Marines (Ranged) | J4: Rogal Dorn Battle Tank (Imperial Guard) | P4: Results | AA4: Keyword Values (helper columns)
A5: Use | B5: Qty | C5: Weapon | D5: A | E5: BS | F5: S | G5: AP | H5: D | I5: Modifier | J5: T | K5: W | L5: Sv | M5: InSv | N5: FNP | O5: Modifiers | P5: Attacks | Q5: Hits | R5: Auto Wounds | S5: Wounds | T5: Mortal Wounds | U5: Unsaved | V5: Dmg per Attack | W5: Total Damage | X5: Models Killed | Y5: Summary | AA5: Torrent | AB5: Lethal Hits | AC5: Sustained Hits | AD5: Dev Wounds | AE5: Twin-Linked | AF5: Lance | AG5: Heavy | AH5: Rapid Fire | AI5: Blast | AJ5: Cleave | AK5: Melta | AL5: Ignores Cover | AM5: Psychic | AN5: Crit Wound On | AO5: Hit Need | AP5: Wound Need | AQ5: Save Need | AR5: Attacks per Kill | AS5: Hit Mod | AT5: Wound Mod | AU5: AP Mod | AV5: Dmg Mod | AW5: Hit Reroll | AX5: Wound Reroll | AY5: Crit Hit Chance | AZ5: Attacks Mod | BA5: Strength Mod | BB5: BS Mod | BC5: Crit Hit On | BD5: Save Mod (Attacker) | BF5: Ranged Units | BH5: Target Units
A6: TRUE | B6: 2 | C6: {=IFERROR(_xlfn.LET(_xlpm.k,_xlfn.XMATCH(TRIM($C$3),Factions[Faction]),_xlpm.u,$C$4,_xlpm.blk,FACTIONBLOCK(_xlpm.k),_xlpm.srcUnit,_xlfn.CHOOSECOLS(_xlpm.blk,1),_xlpm.srcWeapon,_xlfn.CHOOSECOLS(_xlpm.blk,16),_xlpm.srcType,_xlfn.CHOOSECOLS(_xlpm.blk,17),_xlpm.unitFill,_xlfn.SCAN("",_xlpm.srcUnit,_xlfn.LAMBDA(_xlpm.a,_xlpm.v,IF(_xlpm.v<>"",_xlpm.v,_xlpm.a))),_xlpm.names,_xlfn._xlws.FILTER(_xlpm.srcWeapon,(_xlpm.unitFill=_xlpm.u)*(_xlpm.srcWeapon<>"")*(_xlpm.srcType="Ranged")),_xlpm.stats,_xlfn.CHOOSECOLS(_xlpm.blk,_xlfn.SEQUENCE(1,7,20)),_xlpm.statNames,_xlfn.CHOOSECOLS(_xlpm.blk,20),_xlpm.idx,_xlfn.XMATCH(_xlpm.names,_xlpm.statNames),_xlpm.res,_xlfn.CHOOSEROWS(_xlpm.stats,_xlfn._xlws.FILTER(_xlpm.idx,ISNUMBER(_xlpm.idx))),IF(_xlpm.res="","",_xlpm.res)),"")} -> Blight Launcher | D6: D3 | E6: 3 | F6: 6 | G6: -1 | H6: 2 | I6: Blast, Lethal Hits | J6: {=IF($C$6="","",_xlfn.XLOOKUP($J$4,_xlfn.CHOOSECOLS(AllTargets,1),_xlfn.CHOOSECOLS(AllTargets,COLUMN()-COLUMN($I$6)+1),""))} -> 12 | K6: {=IF($C$6="","",_xlfn.XLOOKUP($J$4,_xlfn.CHOOSECOLS(AllTargets,1),_xlfn.CHOOSECOLS(AllTargets,COLUMN()-COLUMN($I$6)+1),""))} -> 17 | L6: {=IF($C$6="","",_xlfn.XLOOKUP($J$4,_xlfn.CHOOSECOLS(AllTargets,1),_xlfn.CHOOSECOLS(AllTargets,COLUMN()-COLUMN($I$6)+1),""))} -> 2 | M6: {=IF($C$6="","",_xlfn.XLOOKUP($J$4,_xlfn.CHOOSECOLS(AllTargets,1),_xlfn.CHOOSECOLS(AllTargets,COLUMN()-COLUMN($I$6)+1),""))} -> - | N6: {=IF($C$6="","",_xlfn.XLOOKUP($J$4,_xlfn.CHOOSECOLS(AllTargets,1),_xlfn.CHOOSECOLS(AllTargets,COLUMN()-COLUMN($I$6)+1),""))} -> - | O6: {=IF($C$6="","",_xlfn.XLOOKUP($J$4,_xlfn.CHOOSECOLS(AllTargets,1),_xlfn.CHOOSECOLS(AllTargets,COLUMN()-COLUMN($I$6)+1),""))} | P6: {=IF(OR($C6="",NOT($A6)),"",N($B6)*(MAX(1,DICEAVG($D6)+$AZ6)+$AH6*($E$3="Yes")+($AI6+$AJ6)*INT($H$3/5)))} -> 8 | Q6: =IF(OR($C6="",NOT($A6)),"",IF($AA6,$P6,_xlfn.LET(_xlpm.p,MAX((7-$AO6)/6,(7-$BC6)/6),_xlpm.ph,IF($AW6=2,_xlpm.p+(1-_xlpm.p)*_xlpm.p,IF($AW6=1,_xlpm.p+_xlpm.p/6,_xlpm.p)),$P6*_xlpm.ph+$P6*$AY6*$AC6))) -> 5.3333333 | R6: =IF(OR($C6="",NOT($A6)),"",IF(AND($AB6,NOT($AA6)),$P6*$AY6,0)) -> 1.3333333 | S6: =IF(OR($C6="",NOT($A6)),"",_xlfn.LET(_xlpm.n,$Q6-$R6,_xlpm.pW,(7-$AP6)/6,_xlpm.pC,(7-$AN6)/6,_xlpm.pT,MAX(_xlpm.pW,_xlpm.pC),_xlpm.rr,$AX6,_xlpm.n*IF(_xlpm.rr=2,1-(1-_xlpm.pT)^2,IF(_xlpm.rr=1,_xlpm.pT+_xlpm.pT/6,_xlpm.pT))+$R6)) -> 2 | T6: =IF(OR($C6="",NOT($A6)),"",IF($AD6,_xlfn.LET(_xlpm.n,$Q6-$R6,_xlpm.pW,(7-$AP6)/6,_xlpm.pC,(7-$AN6)/6,_xlpm.pT,MAX(_xlpm.pW,_xlpm.pC),_xlpm.rr,$AX6,_xlpm.n*IF(_xlpm.rr=2,_xlpm.pC+(1-_xlpm.pT)*_xlpm.pC,IF(_xlpm.rr=1,_xlpm.pC+_xlpm.pC/6,_xlpm.pC))),0)) -> 0 | U6: =IF(OR($C6="",NOT($A6)),"",($S6-$T6)*($AQ6-1)/6) -> 0.66666667 | V6: {=IF(OR($C6="",NOT($A6)),"",MAX(1,DICEAVG($H6)+$AK6*($E$3="Yes")+$AV6+$AH$3))} -> 2 | W6: =IF(OR($C6="",NOT($A6)),"",($U6+$T6)*IF(N($K$6)>0,MIN($V6,$K$6),$V6)*($AA$3-1)/6) -> 1.3333333 | X6: =IF(OR($C6="",NOT($A6),$AR6=""),"",MIN($H$3,($U6+$T6)/$AR6)) -> 0.074074074 | Y6: =IF(OR($C6="",NOT($A6)),"",TEXT($W6,"0.00")&" dmg"&IF($X6="","",", "&TEXT($X6,"0.00")&" kills")) -> 1.33 dmg, 0.07 kills | AA6: {=IF($C6="","",KW(($I6&", "&$AC$3),"Torrent")=TRUE)} -> FALSE | AB6: {=IF($C6="","",KW(($I6&", "&$AC$3),"Lethal Hits")=TRUE)} -> TRUE | AC6: {=IF($C6="","",N(KW(($I6&", "&$AC$3),"Sustained Hits")))} -> 0 | AD6: {=IF($C6="","",KW(($I6&", "&$AC$3),"Devastating Wounds")=TRUE)} -> FALSE | AE6: {=IF($C6="","",KW(($I6&", "&$AC$3),"Twin-Linked")=TRUE)} -> FALSE | AF6: {=IF($C6="","",KW(($I6&", "&$AC$3),"Lance")=TRUE)} -> FALSE | AG6: {=IF($C6="","",KW(($I6&", "&$AC$3),"Heavy")=TRUE)} -> FALSE | AH6: {=IF($C6="","",N(KW(($I6&", "&$AC$3),"Rapid Fire")))} -> 0 | AI6: {=IF($C6="","",N(KW(($I6&", "&$AC$3),"Blast")))} -> 1 | AJ6: {=IF($C6="","",N(KW(($I6&", "&$AC$3),"Cleave")))} -> 0 | AK6: {=IF($C6="","",N(KW(($I6&", "&$AC$3),"Melta")))} -> 0 | AL6: {=IF($C6="","",KW(($I6&", "&$AC$3),"Ignores Cover")=TRUE)} -> FALSE | AM6: {=IF($C6="","",KW(($I6&", "&$AC$3),"Psychic")=TRUE)} -> FALSE | AN6: {=IF($C6="","",_xlfn.LET(_xlpm.src,$I6&", "&$AC$3,_xlpm.a,KWANTI(_xlpm.src,($O$6&", "&$AD$3)),_xlpm.c,KWMIN(_xlpm.src,"Critical Wounds"),MIN(_xlpm.a,IF(ISNUMBER(_xlpm.c),MEDIAN(2,6,_xlpm.c),6))))} -> 6 | AO6: {=IF($C6="","",IF($AA6,0,_xlfn.LET(_xlpm.src,$I6&", "&$AC$3,_xlpm.stat,$F$3="Yes",IF(KW(_xlpm.src,"Snap Shooting")=TRUE,IF(_xlpm.stat,4,6),_xlfn.LET(_xlpm.psy,$AM6,_xlpm.hv,$AG6*_xlpm.stat,_xlpm.dmg,-($I$3="Yes"),_xlpm.am,$AS6,_xlpm.tm,$AI$3,_xlpm.mods,IF(_xlpm.psy,MAX(0,_xlpm.hv)+MAX(0,_xlpm.am)+MAX(0,_xlpm.tm),_xlpm.hv+_xlpm.dmg+_xlpm.am+_xlpm.tm),_xlpm.cov,AND(OR($G$3="Yes",$AB$3),NOT($AL6),NOT(_xlpm.psy)),_xlpm.bs,MIN(6,MAX(2,$E6+IF(_xlpm.psy,MIN(0,$BB6),$BB6+_xlpm.cov))),MEDIAN(2,6,_xlpm.bs-MAX(-1,MIN(1,_xlpm.mods))))))))} -> 3 | AP6: =IF($C6="","",_xlfn.LET(_xlpm.s,MAX(1,$F6+$BA6),_xlpm.t,MAX(1,N($J$6)+$AF$3),_xlpm.base,7-(1+(_xlpm.s>=2*_xlpm.t)+(_xlpm.s>_xlpm.t)+(_xlpm.s>=_xlpm.t)+(_xlpm.s>_xlpm.t/2)),MEDIAN(2,6,_xlpm.base-MAX(-1,MIN(1,$AT6+$AJ$3))))) -> 6 | AQ6: =IF($C6="","",_xlfn.LET(_xlpm.ap,MIN(0,$G6+$AU6+$AK$3),_xlpm.arm,$L$6-_xlpm.ap-$AG$3-$BD6,_xlpm.inv,IF(ISNUMBER($M$6),$M$6,7),MEDIAN(2,7,MIN(_xlpm.arm,_xlpm.inv)))) -> 3 | AR6: =IF(OR($C6="",N($K$6)<=0),"",ROUNDUP($K$6/MIN($V6,$K$6),0)/(($AA$3-1)/6)) -> 9 | AS6: {=IF($C6="","",KWSUM(($I6&", "&$AC$3),"Hit Modifier"))} -> 0 | AT6: {=IF($C6="","",KWSUM(($I6&", "&$AC$3),"Wound Modifier"))} -> 0 | AU6: {=IF($C6="","",KWSUM(($I6&", "&$AC$3),"AP Modifier"))} -> 0 | AV6: {=IF($C6="","",KWSUM(($I6&", "&$AC$3),"Damage Modifier"))} -> 0 | AW6: {=IF($C6="","",_xlfn.LET(_xlpm.src,$I6&", "&$AC$3,IF(KW(_xlpm.src,"Snap Shooting")=TRUE,0,_xlfn.LET(_xlpm.full,ISNUMBER(_xlfn.XMATCH("Reroll Hits",TRIM(_xlfn.TEXTSPLIT(_xlpm.src,",")))),_xlpm.r,KW(_xlpm.src,"Reroll Hits"),IF(_xlpm.full,2,IF(N(_xlpm.r)>=1,1,0))))))} -> 0 | AX6: {=IF($C6="","",_xlfn.LET(_xlpm.src,$I6&", "&$AC$3,_xlpm.full,OR($AE6,ISNUMBER(_xlfn.XMATCH("Reroll Wounds",TRIM(_xlfn.TEXTSPLIT(_xlpm.src,","))))),_xlpm.r,KW(_xlpm.src,"Reroll Wounds"),IF(_xlpm.full,2,IF(N(_xlpm.r)>=1,1,0))))} -> 0 | AY6: =IF($C6="","",IF($AA6,0,_xlfn.LET(_xlpm.pc,(7-$BC6)/6,_xlpm.p,MAX((7-$AO6)/6,_xlpm.pc),IF($AW6=2,_xlpm.pc+(1-_xlpm.p)*_xlpm.pc,IF($AW6=1,_xlpm.pc+_xlpm.pc/6,_xlpm.pc))))) -> 0.16666667 | AZ6: {=IF($C6="","",KWSUM($I6&", "&$AC$3,"Attacks Modifier"))} -> 0 | BA6: {=IF($C6="","",KWSUM($I6&", "&$AC$3,"Strength Modifier"))} -> 0 | BB6: {=IF($C6="","",KWSUM($I6&", "&$AC$3,"BS Modifier"))} -> 0 | BC6: {=IF($C6="","",_xlfn.LET(_xlpm.src,$I6&", "&$AC$3,_xlpm.c,KWMIN(_xlpm.src,"Critical Hits"),IF(KW(_xlpm.src,"Snap Shooting")=TRUE,6,IF(ISNUMBER(_xlpm.c),MEDIAN(2,6,_xlpm.c),6))))} -> 6 | BD6: {=IF($C6="","",KWSUM($I6&", "&$AC$3,"Save Modifier"))} -> 0 | BF6: {=_xlfn.LET(_xlpm.k,_xlfn.XMATCH(TRIM($C$3),Factions[Faction]),_xlpm.blk,FACTIONBLOCK(_xlpm.k),_xlpm.unitFill,_xlfn.SCAN("",_xlfn.CHOOSECOLS(_xlpm.blk,1),_xlfn.LAMBDA(_xlpm.a,_xlpm.v,IF(_xlpm.v<>"",_xlpm.v,_xlpm.a))),IFERROR(_xlfn.UNIQUE(_xlfn._xlws.FILTER(_xlpm.unitFill,(_xlpm.unitFill<>"")*(_xlfn.CHOOSECOLS(_xlpm.blk,17)="Ranged"))),"No ranged units"))} -> Myphitic Blight Hauler | BH6: {=_xlfn.LET(_xlpm.n,_xlfn.CHOOSECOLS(AllTargets,1),_xlfn.UNIQUE(_xlfn._xlws.FILTER(_xlpm.n,_xlpm.n<>"")))} -> Myphitic Blight Hauler (DeathGuard)
A7: TRUE | B7: 3 | C7: Boltgun | D7: 2 | E7: 3 | F7: 5 | G7: -1 | H7: 1 | I7: Lethal Hits | P7: {=IF(OR($C7="",NOT($A7)),"",N($B7)*(MAX(1,DICEAVG($D7)+$AZ7)+$AH7*($E$3="Yes")+($AI7+$AJ7)*INT($H$3/5)))} -> 6 | Q7: =IF(OR($C7="",NOT($A7)),"",IF($AA7,$P7,_xlfn.LET(_xlpm.p,MAX((7-$AO7)/6,(7-$BC7)/6),_xlpm.ph,IF($AW7=2,_xlpm.p+(1-_xlpm.p)*_xlpm.p,IF($AW7=1,_xlpm.p+_xlpm.p/6,_xlpm.p)),$P7*_xlpm.ph+$P7*$AY7*$AC7))) -> 4 | R7: =IF(OR($C7="",NOT($A7)),"",IF(AND($AB7,NOT($AA7)),$P7*$AY7,0)) -> 1 | S7: =IF(OR($C7="",NOT($A7)),"",_xlfn.LET(_xlpm.n,$Q7-$R7,_xlpm.pW,(7-$AP7)/6,_xlpm.pC,(7-$AN7)/6,_xlpm.pT,MAX(_xlpm.pW,_xlpm.pC),_xlpm.rr,$AX7,_xlpm.n*IF(_xlpm.rr=2,1-(1-_xlpm.pT)^2,IF(_xlpm.rr=1,_xlpm.pT+_xlpm.pT/6,_xlpm.pT))+$R7)) -> 1.5 | T7: =IF(OR($C7="",NOT($A7)),"",IF($AD7,_xlfn.LET(_xlpm.n,$Q7-$R7,_xlpm.pW,(7-$AP7)/6,_xlpm.pC,(7-$AN7)/6,_xlpm.pT,MAX(_xlpm.pW,_xlpm.pC),_xlpm.rr,$AX7,_xlpm.n*IF(_xlpm.rr=2,_xlpm.pC+(1-_xlpm.pT)*_xlpm.pC,IF(_xlpm.rr=1,_xlpm.pC+_xlpm.pC/6,_xlpm.pC))),0)) -> 0 | U7: =IF(OR($C7="",NOT($A7)),"",($S7-$T7)*($AQ7-1)/6) -> 0.5 | V7: {=IF(OR($C7="",NOT($A7)),"",MAX(1,DICEAVG($H7)+$AK7*($E$3="Yes")+$AV7+$AH$3))} -> 1 | W7: =IF(OR($C7="",NOT($A7)),"",($U7+$T7)*IF(N($K$6)>0,MIN($V7,$K$6),$V7)*($AA$3-1)/6) -> 0.5 | X7: =IF(OR($C7="",NOT($A7),$AR7=""),"",MIN($H$3,($U7+$T7)/$AR7)) -> 0.029411765 | Y7: =IF(OR($C7="",NOT($A7)),"",TEXT($W7,"0.00")&" dmg"&IF($X7="","",", "&TEXT($X7,"0.00")&" kills")) -> 0.50 dmg, 0.03 kills | AA7: {=IF($C7="","",KW(($I7&", "&$AC$3),"Torrent")=TRUE)} -> FALSE | AB7: {=IF($C7="","",KW(($I7&", "&$AC$3),"Lethal Hits")=TRUE)} -> TRUE | AC7: {=IF($C7="","",N(KW(($I7&", "&$AC$3),"Sustained Hits")))} -> 0 | AD7: {=IF($C7="","",KW(($I7&", "&$AC$3),"Devastating Wounds")=TRUE)} -> FALSE | AE7: {=IF($C7="","",KW(($I7&", "&$AC$3),"Twin-Linked")=TRUE)} -> FALSE | AF7: {=IF($C7="","",KW(($I7&", "&$AC$3),"Lance")=TRUE)} -> FALSE | AG7: {=IF($C7="","",KW(($I7&", "&$AC$3),"Heavy")=TRUE)} -> FALSE | AH7: {=IF($C7="","",N(KW(($I7&", "&$AC$3),"Rapid Fire")))} -> 0 | AI7: {=IF($C7="","",N(KW(($I7&", "&$AC$3),"Blast")))} -> 0 | AJ7: {=IF($C7="","",N(KW(($I7&", "&$AC$3),"Cleave")))} -> 0 | AK7: {=IF($C7="","",N(KW(($I7&", "&$AC$3),"Melta")))} -> 0 | AL7: {=IF($C7="","",KW(($I7&", "&$AC$3),"Ignores Cover")=TRUE)} -> FALSE | AM7: {=IF($C7="","",KW(($I7&", "&$AC$3),"Psychic")=TRUE)} -> FALSE | AN7: {=IF($C7="","",_xlfn.LET(_xlpm.src,$I7&", "&$AC$3,_xlpm.a,KWANTI(_xlpm.src,($O$6&", "&$AD$3)),_xlpm.c,KWMIN(_xlpm.src,"Critical Wounds"),MIN(_xlpm.a,IF(ISNUMBER(_xlpm.c),MEDIAN(2,6,_xlpm.c),6))))} -> 6 | AO7: {=IF($C7="","",IF($AA7,0,_xlfn.LET(_xlpm.src,$I7&", "&$AC$3,_xlpm.stat,$F$3="Yes",IF(KW(_xlpm.src,"Snap Shooting")=TRUE,IF(_xlpm.stat,4,6),_xlfn.LET(_xlpm.psy,$AM7,_xlpm.hv,$AG7*_xlpm.stat,_xlpm.dmg,-($I$3="Yes"),_xlpm.am,$AS7,_xlpm.tm,$AI$3,_xlpm.mods,IF(_xlpm.psy,MAX(0,_xlpm.hv)+MAX(0,_xlpm.am)+MAX(0,_xlpm.tm),_xlpm.hv+_xlpm.dmg+_xlpm.am+_xlpm.tm),_xlpm.cov,AND(OR($G$3="Yes",$AB$3),NOT($AL7),NOT(_xlpm.psy)),_xlpm.bs,MIN(6,MAX(2,$E7+IF(_xlpm.psy,MIN(0,$BB7),$BB7+_xlpm.cov))),MEDIAN(2,6,_xlpm.bs-MAX(-1,MIN(1,_xlpm.mods))))))))} -> 3 | AP7: =IF($C7="","",_xlfn.LET(_xlpm.s,MAX(1,$F7+$BA7),_xlpm.t,MAX(1,N($J$6)+$AF$3),_xlpm.base,7-(1+(_xlpm.s>=2*_xlpm.t)+(_xlpm.s>_xlpm.t)+(_xlpm.s>=_xlpm.t)+(_xlpm.s>_xlpm.t/2)),MEDIAN(2,6,_xlpm.base-MAX(-1,MIN(1,$AT7+$AJ$3))))) -> 6 | AQ7: =IF($C7="","",_xlfn.LET(_xlpm.ap,MIN(0,$G7+$AU7+$AK$3),_xlpm.arm,$L$6-_xlpm.ap-$AG$3-$BD7,_xlpm.inv,IF(ISNUMBER($M$6),$M$6,7),MEDIAN(2,7,MIN(_xlpm.arm,_xlpm.inv)))) -> 3 | AR7: =IF(OR($C7="",N($K$6)<=0),"",ROUNDUP($K$6/MIN($V7,$K$6),0)/(($AA$3-1)/6)) -> 17 | AS7: {=IF($C7="","",KWSUM(($I7&", "&$AC$3),"Hit Modifier"))} -> 0 | AT7: {=IF($C7="","",KWSUM(($I7&", "&$AC$3),"Wound Modifier"))} -> 0 | AU7: {=IF($C7="","",KWSUM(($I7&", "&$AC$3),"AP Modifier"))} -> 0 | AV7: {=IF($C7="","",KWSUM(($I7&", "&$AC$3),"Damage Modifier"))} -> 0 | AW7: {=IF($C7="","",_xlfn.LET(_xlpm.src,$I7&", "&$AC$3,IF(KW(_xlpm.src,"Snap Shooting")=TRUE,0,_xlfn.LET(_xlpm.full,ISNUMBER(_xlfn.XMATCH("Reroll Hits",TRIM(_xlfn.TEXTSPLIT(_xlpm.src,",")))),_xlpm.r,KW(_xlpm.src,"Reroll Hits"),IF(_xlpm.full,2,IF(N(_xlpm.r)>=1,1,0))))))} -> 0 | AX7: {=IF($C7="","",_xlfn.LET(_xlpm.src,$I7&", "&$AC$3,_xlpm.full,OR($AE7,ISNUMBER(_xlfn.XMATCH("Reroll Wounds",TRIM(_xlfn.TEXTSPLIT(_xlpm.src,","))))),_xlpm.r,KW(_xlpm.src,"Reroll Wounds"),IF(_xlpm.full,2,IF(N(_xlpm.r)>=1,1,0))))} -> 0 | AY7: =IF($C7="","",IF($AA7,0,_xlfn.LET(_xlpm.pc,(7-$BC7)/6,_xlpm.p,MAX((7-$AO7)/6,_xlpm.pc),IF($AW7=2,_xlpm.pc+(1-_xlpm.p)*_xlpm.pc,IF($AW7=1,_xlpm.pc+_xlpm.pc/6,_xlpm.pc))))) -> 0.16666667 | AZ7: {=IF($C7="","",KWSUM($I7&", "&$AC$3,"Attacks Modifier"))} -> 0 | BA7: {=IF($C7="","",KWSUM($I7&", "&$AC$3,"Strength Modifier"))} -> 0 | BB7: {=IF($C7="","",KWSUM($I7&", "&$AC$3,"BS Modifier"))} -> 0 | BC7: {=IF($C7="","",_xlfn.LET(_xlpm.src,$I7&", "&$AC$3,_xlpm.c,KWMIN(_xlpm.src,"Critical Hits"),IF(KW(_xlpm.src,"Snap Shooting")=TRUE,6,IF(ISNUMBER(_xlpm.c),MEDIAN(2,6,_xlpm.c),6))))} -> 6 | BD7: {=IF($C7="","",KWSUM($I7&", "&$AC$3,"Save Modifier"))} -> 0 | BF7: Plague Marines (Ranged) | BH7: Plague Marines (Ranged) (DeathGuard)
A8: TRUE | B8: 2 | C8: Plague Spewer | D8: D6 | E8: - | F8: 5 | G8: -1 | H8: 1 | I8: Anti-Infantry 2+, Torrent | P8: {=IF(OR($C8="",NOT($A8)),"",N($B8)*(MAX(1,DICEAVG($D8)+$AZ8)+$AH8*($E$3="Yes")+($AI8+$AJ8)*INT($H$3/5)))} -> 7 | Q8: =IF(OR($C8="",NOT($A8)),"",IF($AA8,$P8,_xlfn.LET(_xlpm.p,MAX((7-$AO8)/6,(7-$BC8)/6),_xlpm.ph,IF($AW8=2,_xlpm.p+(1-_xlpm.p)*_xlpm.p,IF($AW8=1,_xlpm.p+_xlpm.p/6,_xlpm.p)),$P8*_xlpm.ph+$P8*$AY8*$AC8))) -> 7 | R8: =IF(OR($C8="",NOT($A8)),"",IF(AND($AB8,NOT($AA8)),$P8*$AY8,0)) -> 0 | S8: =IF(OR($C8="",NOT($A8)),"",_xlfn.LET(_xlpm.n,$Q8-$R8,_xlpm.pW,(7-$AP8)/6,_xlpm.pC,(7-$AN8)/6,_xlpm.pT,MAX(_xlpm.pW,_xlpm.pC),_xlpm.rr,$AX8,_xlpm.n*IF(_xlpm.rr=2,1-(1-_xlpm.pT)^2,IF(_xlpm.rr=1,_xlpm.pT+_xlpm.pT/6,_xlpm.pT))+$R8)) -> 1.1666667 | T8: =IF(OR($C8="",NOT($A8)),"",IF($AD8,_xlfn.LET(_xlpm.n,$Q8-$R8,_xlpm.pW,(7-$AP8)/6,_xlpm.pC,(7-$AN8)/6,_xlpm.pT,MAX(_xlpm.pW,_xlpm.pC),_xlpm.rr,$AX8,_xlpm.n*IF(_xlpm.rr=2,_xlpm.pC+(1-_xlpm.pT)*_xlpm.pC,IF(_xlpm.rr=1,_xlpm.pC+_xlpm.pC/6,_xlpm.pC))),0)) -> 0 | U8: =IF(OR($C8="",NOT($A8)),"",($S8-$T8)*($AQ8-1)/6) -> 0.38888889 | V8: {=IF(OR($C8="",NOT($A8)),"",MAX(1,DICEAVG($H8)+$AK8*($E$3="Yes")+$AV8+$AH$3))} -> 1 | W8: =IF(OR($C8="",NOT($A8)),"",($U8+$T8)*IF(N($K$6)>0,MIN($V8,$K$6),$V8)*($AA$3-1)/6) -> 0.38888889 | X8: =IF(OR($C8="",NOT($A8),$AR8=""),"",MIN($H$3,($U8+$T8)/$AR8)) -> 0.022875817 | Y8: =IF(OR($C8="",NOT($A8)),"",TEXT($W8,"0.00")&" dmg"&IF($X8="","",", "&TEXT($X8,"0.00")&" kills")) -> 0.39 dmg, 0.02 kills | AA8: {=IF($C8="","",KW(($I8&", "&$AC$3),"Torrent")=TRUE)} -> TRUE | AB8: {=IF($C8="","",KW(($I8&", "&$AC$3),"Lethal Hits")=TRUE)} -> FALSE | AC8: {=IF($C8="","",N(KW(($I8&", "&$AC$3),"Sustained Hits")))} -> 0 | AD8: {=IF($C8="","",KW(($I8&", "&$AC$3),"Devastating Wounds")=TRUE)} -> FALSE | AE8: {=IF($C8="","",KW(($I8&", "&$AC$3),"Twin-Linked")=TRUE)} -> FALSE | AF8: {=IF($C8="","",KW(($I8&", "&$AC$3),"Lance")=TRUE)} -> FALSE | AG8: {=IF($C8="","",KW(($I8&", "&$AC$3),"Heavy")=TRUE)} -> FALSE | AH8: {=IF($C8="","",N(KW(($I8&", "&$AC$3),"Rapid Fire")))} -> 0 | AI8: {=IF($C8="","",N(KW(($I8&", "&$AC$3),"Blast")))} -> 0 | AJ8: {=IF($C8="","",N(KW(($I8&", "&$AC$3),"Cleave")))} -> 0 | AK8: {=IF($C8="","",N(KW(($I8&", "&$AC$3),"Melta")))} -> 0 | AL8: {=IF($C8="","",KW(($I8&", "&$AC$3),"Ignores Cover")=TRUE)} -> FALSE | AM8: {=IF($C8="","",KW(($I8&", "&$AC$3),"Psychic")=TRUE)} -> FALSE | AN8: {=IF($C8="","",_xlfn.LET(_xlpm.src,$I8&", "&$AC$3,_xlpm.a,KWANTI(_xlpm.src,($O$6&", "&$AD$3)),_xlpm.c,KWMIN(_xlpm.src,"Critical Wounds"),MIN(_xlpm.a,IF(ISNUMBER(_xlpm.c),MEDIAN(2,6,_xlpm.c),6))))} -> 6 | AO8: {=IF($C8="","",IF($AA8,0,_xlfn.LET(_xlpm.src,$I8&", "&$AC$3,_xlpm.stat,$F$3="Yes",IF(KW(_xlpm.src,"Snap Shooting")=TRUE,IF(_xlpm.stat,4,6),_xlfn.LET(_xlpm.psy,$AM8,_xlpm.hv,$AG8*_xlpm.stat,_xlpm.dmg,-($I$3="Yes"),_xlpm.am,$AS8,_xlpm.tm,$AI$3,_xlpm.mods,IF(_xlpm.psy,MAX(0,_xlpm.hv)+MAX(0,_xlpm.am)+MAX(0,_xlpm.tm),_xlpm.hv+_xlpm.dmg+_xlpm.am+_xlpm.tm),_xlpm.cov,AND(OR($G$3="Yes",$AB$3),NOT($AL8),NOT(_xlpm.psy)),_xlpm.bs,MIN(6,MAX(2,$E8+IF(_xlpm.psy,MIN(0,$BB8),$BB8+_xlpm.cov))),MEDIAN(2,6,_xlpm.bs-MAX(-1,MIN(1,_xlpm.mods))))))))} -> 0 | AP8: =IF($C8="","",_xlfn.LET(_xlpm.s,MAX(1,$F8+$BA8),_xlpm.t,MAX(1,N($J$6)+$AF$3),_xlpm.base,7-(1+(_xlpm.s>=2*_xlpm.t)+(_xlpm.s>_xlpm.t)+(_xlpm.s>=_xlpm.t)+(_xlpm.s>_xlpm.t/2)),MEDIAN(2,6,_xlpm.base-MAX(-1,MIN(1,$AT8+$AJ$3))))) -> 6 | AQ8: =IF($C8="","",_xlfn.LET(_xlpm.ap,MIN(0,$G8+$AU8+$AK$3),_xlpm.arm,$L$6-_xlpm.ap-$AG$3-$BD8,_xlpm.inv,IF(ISNUMBER($M$6),$M$6,7),MEDIAN(2,7,MIN(_xlpm.arm,_xlpm.inv)))) -> 3 | AR8: =IF(OR($C8="",N($K$6)<=0),"",ROUNDUP($K$6/MIN($V8,$K$6),0)/(($AA$3-1)/6)) -> 17 | AS8: {=IF($C8="","",KWSUM(($I8&", "&$AC$3),"Hit Modifier"))} -> 0 | AT8: {=IF($C8="","",KWSUM(($I8&", "&$AC$3),"Wound Modifier"))} -> 0 | AU8: {=IF($C8="","",KWSUM(($I8&", "&$AC$3),"AP Modifier"))} -> 0 | AV8: {=IF($C8="","",KWSUM(($I8&", "&$AC$3),"Damage Modifier"))} -> 0 | AW8: {=IF($C8="","",_xlfn.LET(_xlpm.src,$I8&", "&$AC$3,IF(KW(_xlpm.src,"Snap Shooting")=TRUE,0,_xlfn.LET(_xlpm.full,ISNUMBER(_xlfn.XMATCH("Reroll Hits",TRIM(_xlfn.TEXTSPLIT(_xlpm.src,",")))),_xlpm.r,KW(_xlpm.src,"Reroll Hits"),IF(_xlpm.full,2,IF(N(_xlpm.r)>=1,1,0))))))} -> 0 | AX8: {=IF($C8="","",_xlfn.LET(_xlpm.src,$I8&", "&$AC$3,_xlpm.full,OR($AE8,ISNUMBER(_xlfn.XMATCH("Reroll Wounds",TRIM(_xlfn.TEXTSPLIT(_xlpm.src,","))))),_xlpm.r,KW(_xlpm.src,"Reroll Wounds"),IF(_xlpm.full,2,IF(N(_xlpm.r)>=1,1,0))))} -> 0 | AY8: =IF($C8="","",IF($AA8,0,_xlfn.LET(_xlpm.pc,(7-$BC8)/6,_xlpm.p,MAX((7-$AO8)/6,_xlpm.pc),IF($AW8=2,_xlpm.pc+(1-_xlpm.p)*_xlpm.pc,IF($AW8=1,_xlpm.pc+_xlpm.pc/6,_xlpm.pc))))) -> 0 | AZ8: {=IF($C8="","",KWSUM($I8&", "&$AC$3,"Attacks Modifier"))} -> 0 | BA8: {=IF($C8="","",KWSUM($I8&", "&$AC$3,"Strength Modifier"))} -> 0 | BB8: {=IF($C8="","",KWSUM($I8&", "&$AC$3,"BS Modifier"))} -> 0 | BC8: {=IF($C8="","",_xlfn.LET(_xlpm.src,$I8&", "&$AC$3,_xlpm.c,KWMIN(_xlpm.src,"Critical Hits"),IF(KW(_xlpm.src,"Snap Shooting")=TRUE,6,IF(ISNUMBER(_xlpm.c),MEDIAN(2,6,_xlpm.c),6))))} -> 6 | BD8: {=IF($C8="","",KWSUM($I8&", "&$AC$3,"Save Modifier"))} -> 0 | BF8: Deathshroud Terminators | BH8: Deathshroud Terminators (DeathGuard)
A9: TRUE | B9: 2 | C9: Plasma Gun - Standard | D9: 1 | E9: 3 | F9: 7 | G9: -2 | H9: 1 | I9: Rapid Fire 1 | P9: {=IF(OR($C9="",NOT($A9)),"",N($B9)*(MAX(1,DICEAVG($D9)+$AZ9)+$AH9*($E$3="Yes")+($AI9+$AJ9)*INT($H$3/5)))} -> 4 | Q9: =IF(OR($C9="",NOT($A9)),"",IF($AA9,$P9,_xlfn.LET(_xlpm.p,MAX((7-$AO9)/6,(7-$BC9)/6),_xlpm.ph,IF($AW9=2,_xlpm.p+(1-_xlpm.p)*_xlpm.p,IF($AW9=1,_xlpm.p+_xlpm.p/6,_xlpm.p)),$P9*_xlpm.ph+$P9*$AY9*$AC9))) -> 2.6666667 | R9: =IF(OR($C9="",NOT($A9)),"",IF(AND($AB9,NOT($AA9)),$P9*$AY9,0)) -> 0 | S9: =IF(OR($C9="",NOT($A9)),"",_xlfn.LET(_xlpm.n,$Q9-$R9,_xlpm.pW,(7-$AP9)/6,_xlpm.pC,(7-$AN9)/6,_xlpm.pT,MAX(_xlpm.pW,_xlpm.pC),_xlpm.rr,$AX9,_xlpm.n*IF(_xlpm.rr=2,1-(1-_xlpm.pT)^2,IF(_xlpm.rr=1,_xlpm.pT+_xlpm.pT/6,_xlpm.pT))+$R9)) -> 0.88888889 | T9: =IF(OR($C9="",NOT($A9)),"",IF($AD9,_xlfn.LET(_xlpm.n,$Q9-$R9,_xlpm.pW,(7-$AP9)/6,_xlpm.pC,(7-$AN9)/6,_xlpm.pT,MAX(_xlpm.pW,_xlpm.pC),_xlpm.rr,$AX9,_xlpm.n*IF(_xlpm.rr=2,_xlpm.pC+(1-_xlpm.pT)*_xlpm.pC,IF(_xlpm.rr=1,_xlpm.pC+_xlpm.pC/6,_xlpm.pC))),0)) -> 0 | U9: =IF(OR($C9="",NOT($A9)),"",($S9-$T9)*($AQ9-1)/6) -> 0.44444444 | V9: {=IF(OR($C9="",NOT($A9)),"",MAX(1,DICEAVG($H9)+$AK9*($E$3="Yes")+$AV9+$AH$3))} -> 1 | W9: =IF(OR($C9="",NOT($A9)),"",($U9+$T9)*IF(N($K$6)>0,MIN($V9,$K$6),$V9)*($AA$3-1)/6) -> 0.44444444 | X9: =IF(OR($C9="",NOT($A9),$AR9=""),"",MIN($H$3,($U9+$T9)/$AR9)) -> 0.026143791 | Y9: =IF(OR($C9="",NOT($A9)),"",TEXT($W9,"0.00")&" dmg"&IF($X9="","",", "&TEXT($X9,"0.00")&" kills")) -> 0.44 dmg, 0.03 kills | AA9: {=IF($C9="","",KW(($I9&", "&$AC$3),"Torrent")=TRUE)} -> FALSE | AB9: {=IF($C9="","",KW(($I9&", "&$AC$3),"Lethal Hits")=TRUE)} -> FALSE | AC9: {=IF($C9="","",N(KW(($I9&", "&$AC$3),"Sustained Hits")))} -> 0 | AD9: {=IF($C9="","",KW(($I9&", "&$AC$3),"Devastating Wounds")=TRUE)} -> FALSE | AE9: {=IF($C9="","",KW(($I9&", "&$AC$3),"Twin-Linked")=TRUE)} -> FALSE | AF9: {=IF($C9="","",KW(($I9&", "&$AC$3),"Lance")=TRUE)} -> FALSE | AG9: {=IF($C9="","",KW(($I9&", "&$AC$3),"Heavy")=TRUE)} -> FALSE | AH9: {=IF($C9="","",N(KW(($I9&", "&$AC$3),"Rapid Fire")))} -> 1 | AI9: {=IF($C9="","",N(KW(($I9&", "&$AC$3),"Blast")))} -> 0 | AJ9: {=IF($C9="","",N(KW(($I9&", "&$AC$3),"Cleave")))} -> 0 | AK9: {=IF($C9="","",N(KW(($I9&", "&$AC$3),"Melta")))} -> 0 | AL9: {=IF($C9="","",KW(($I9&", "&$AC$3),"Ignores Cover")=TRUE)} -> FALSE | AM9: {=IF($C9="","",KW(($I9&", "&$AC$3),"Psychic")=TRUE)} -> FALSE | AN9: {=IF($C9="","",_xlfn.LET(_xlpm.src,$I9&", "&$AC$3,_xlpm.a,KWANTI(_xlpm.src,($O$6&", "&$AD$3)),_xlpm.c,KWMIN(_xlpm.src,"Critical Wounds"),MIN(_xlpm.a,IF(ISNUMBER(_xlpm.c),MEDIAN(2,6,_xlpm.c),6))))} -> 6 | AO9: {=IF($C9="","",IF($AA9,0,_xlfn.LET(_xlpm.src,$I9&", "&$AC$3,_xlpm.stat,$F$3="Yes",IF(KW(_xlpm.src,"Snap Shooting")=TRUE,IF(_xlpm.stat,4,6),_xlfn.LET(_xlpm.psy,$AM9,_xlpm.hv,$AG9*_xlpm.stat,_xlpm.dmg,-($I$3="Yes"),_xlpm.am,$AS9,_xlpm.tm,$AI$3,_xlpm.mods,IF(_xlpm.psy,MAX(0,_xlpm.hv)+MAX(0,_xlpm.am)+MAX(0,_xlpm.tm),_xlpm.hv+_xlpm.dmg+_xlpm.am+_xlpm.tm),_xlpm.cov,AND(OR($G$3="Yes",$AB$3),NOT($AL9),NOT(_xlpm.psy)),_xlpm.bs,MIN(6,MAX(2,$E9+IF(_xlpm.psy,MIN(0,$BB9),$BB9+_xlpm.cov))),MEDIAN(2,6,_xlpm.bs-MAX(-1,MIN(1,_xlpm.mods))))))))} -> 3 | AP9: =IF($C9="","",_xlfn.LET(_xlpm.s,MAX(1,$F9+$BA9),_xlpm.t,MAX(1,N($J$6)+$AF$3),_xlpm.base,7-(1+(_xlpm.s>=2*_xlpm.t)+(_xlpm.s>_xlpm.t)+(_xlpm.s>=_xlpm.t)+(_xlpm.s>_xlpm.t/2)),MEDIAN(2,6,_xlpm.base-MAX(-1,MIN(1,$AT9+$AJ$3))))) -> 5 | AQ9: =IF($C9="","",_xlfn.LET(_xlpm.ap,MIN(0,$G9+$AU9+$AK$3),_xlpm.arm,$L$6-_xlpm.ap-$AG$3-$BD9,_xlpm.inv,IF(ISNUMBER($M$6),$M$6,7),MEDIAN(2,7,MIN(_xlpm.arm,_xlpm.inv)))) -> 4 | AR9: =IF(OR($C9="",N($K$6)<=0),"",ROUNDUP($K$6/MIN($V9,$K$6),0)/(($AA$3-1)/6)) -> 17 | AS9: {=IF($C9="","",KWSUM(($I9&", "&$AC$3),"Hit Modifier"))} -> 0 | AT9: {=IF($C9="","",KWSUM(($I9&", "&$AC$3),"Wound Modifier"))} -> 0 | AU9: {=IF($C9="","",KWSUM(($I9&", "&$AC$3),"AP Modifier"))} -> 0 | AV9: {=IF($C9="","",KWSUM(($I9&", "&$AC$3),"Damage Modifier"))} -> 0 | AW9: {=IF($C9="","",_xlfn.LET(_xlpm.src,$I9&", "&$AC$3,IF(KW(_xlpm.src,"Snap Shooting")=TRUE,0,_xlfn.LET(_xlpm.full,ISNUMBER(_xlfn.XMATCH("Reroll Hits",TRIM(_xlfn.TEXTSPLIT(_xlpm.src,",")))),_xlpm.r,KW(_xlpm.src,"Reroll Hits"),IF(_xlpm.full,2,IF(N(_xlpm.r)>=1,1,0))))))} -> 0 | AX9: {=IF($C9="","",_xlfn.LET(_xlpm.src,$I9&", "&$AC$3,_xlpm.full,OR($AE9,ISNUMBER(_xlfn.XMATCH("Reroll Wounds",TRIM(_xlfn.TEXTSPLIT(_xlpm.src,","))))),_xlpm.r,KW(_xlpm.src,"Reroll Wounds"),IF(_xlpm.full,2,IF(N(_xlpm.r)>=1,1,0))))} -> 0 | AY9: =IF($C9="","",IF($AA9,0,_xlfn.LET(_xlpm.pc,(7-$BC9)/6,_xlpm.p,MAX((7-$AO9)/6,_xlpm.pc),IF($AW9=2,_xlpm.pc+(1-_xlpm.p)*_xlpm.pc,IF($AW9=1,_xlpm.pc+_xlpm.pc/6,_xlpm.pc))))) -> 0.16666667 | AZ9: {=IF($C9="","",KWSUM($I9&", "&$AC$3,"Attacks Modifier"))} -> 0 | BA9: {=IF($C9="","",KWSUM($I9&", "&$AC$3,"Strength Modifier"))} -> 0 | BB9: {=IF($C9="","",KWSUM($I9&", "&$AC$3,"BS Modifier"))} -> 0 | BC9: {=IF($C9="","",_xlfn.LET(_xlpm.src,$I9&", "&$AC$3,_xlpm.c,KWMIN(_xlpm.src,"Critical Hits"),IF(KW(_xlpm.src,"Snap Shooting")=TRUE,6,IF(ISNUMBER(_xlpm.c),MEDIAN(2,6,_xlpm.c),6))))} -> 6 | BD9: {=IF($C9="","",KWSUM($I9&", "&$AC$3,"Save Modifier"))} -> 0 | BF9: Lord of Poxes | BH9: Lord of Contagion (DeathGuard)
A10: TRUE | B10: 1 | C10: Plasma Gun - Supercharged | D10: 1 | E10: 3 | F10: 8 | G10: -3 | H10: 2 | I10: Rapid Fire 1 | P10: {=IF(OR($C10="",NOT($A10)),"",N($B10)*(MAX(1,DICEAVG($D10)+$AZ10)+$AH10*($E$3="Yes")+($AI10+$AJ10)*INT($H$3/5)))} -> 2 | Q10: =IF(OR($C10="",NOT($A10)),"",IF($AA10,$P10,_xlfn.LET(_xlpm.p,MAX((7-$AO10)/6,(7-$BC10)/6),_xlpm.ph,IF($AW10=2,_xlpm.p+(1-_xlpm.p)*_xlpm.p,IF($AW10=1,_xlpm.p+_xlpm.p/6,_xlpm.p)),$P10*_xlpm.ph+$P10*$AY10*$AC10))) -> 1.3333333 | R10: =IF(OR($C10="",NOT($A10)),"",IF(AND($AB10,NOT($AA10)),$P10*$AY10,0)) -> 0 | S10: =IF(OR($C10="",NOT($A10)),"",_xlfn.LET(_xlpm.n,$Q10-$R10,_xlpm.pW,(7-$AP10)/6,_xlpm.pC,(7-$AN10)/6,_xlpm.pT,MAX(_xlpm.pW,_xlpm.pC),_xlpm.rr,$AX10,_xlpm.n*IF(_xlpm.rr=2,1-(1-_xlpm.pT)^2,IF(_xlpm.rr=1,_xlpm.pT+_xlpm.pT/6,_xlpm.pT))+$R10)) -> 0.44444444 | T10: =IF(OR($C10="",NOT($A10)),"",IF($AD10,_xlfn.LET(_xlpm.n,$Q10-$R10,_xlpm.pW,(7-$AP10)/6,_xlpm.pC,(7-$AN10)/6,_xlpm.pT,MAX(_xlpm.pW,_xlpm.pC),_xlpm.rr,$AX10,_xlpm.n*IF(_xlpm.rr=2,_xlpm.pC+(1-_xlpm.pT)*_xlpm.pC,IF(_xlpm.rr=1,_xlpm.pC+_xlpm.pC/6,_xlpm.pC))),0)) -> 0 | U10: =IF(OR($C10="",NOT($A10)),"",($S10-$T10)*($AQ10-1)/6) -> 0.2962963 | V10: {=IF(OR($C10="",NOT($A10)),"",MAX(1,DICEAVG($H10)+$AK10*($E$3="Yes")+$AV10+$AH$3))} -> 2 | W10: =IF(OR($C10="",NOT($A10)),"",($U10+$T10)*IF(N($K$6)>0,MIN($V10,$K$6),$V10)*($AA$3-1)/6) -> 0.59259259 | X10: =IF(OR($C10="",NOT($A10),$AR10=""),"",MIN($H$3,($U10+$T10)/$AR10)) -> 0.032921811 | Y10: =IF(OR($C10="",NOT($A10)),"",TEXT($W10,"0.00")&" dmg"&IF($X10="","",", "&TEXT($X10,"0.00")&" kills")) -> 0.59 dmg, 0.03 kills | AA10: {=IF($C10="","",KW(($I10&", "&$AC$3),"Torrent")=TRUE)} -> FALSE | AB10: {=IF($C10="","",KW(($I10&", "&$AC$3),"Lethal Hits")=TRUE)} -> FALSE | AC10: {=IF($C10="","",N(KW(($I10&", "&$AC$3),"Sustained Hits")))} -> 0 | AD10: {=IF($C10="","",KW(($I10&", "&$AC$3),"Devastating Wounds")=TRUE)} -> FALSE | AE10: {=IF($C10="","",KW(($I10&", "&$AC$3),"Twin-Linked")=TRUE)} -> FALSE | AF10: {=IF($C10="","",KW(($I10&", "&$AC$3),"Lance")=TRUE)} -> FALSE | AG10: {=IF($C10="","",KW(($I10&", "&$AC$3),"Heavy")=TRUE)} -> FALSE | AH10: {=IF($C10="","",N(KW(($I10&", "&$AC$3),"Rapid Fire")))} -> 1 | AI10: {=IF($C10="","",N(KW(($I10&", "&$AC$3),"Blast")))} -> 0 | AJ10: {=IF($C10="","",N(KW(($I10&", "&$AC$3),"Cleave")))} -> 0 | AK10: {=IF($C10="","",N(KW(($I10&", "&$AC$3),"Melta")))} -> 0 | AL10: {=IF($C10="","",KW(($I10&", "&$AC$3),"Ignores Cover")=TRUE)} -> FALSE | AM10: {=IF($C10="","",KW(($I10&", "&$AC$3),"Psychic")=TRUE)} -> FALSE | AN10: {=IF($C10="","",_xlfn.LET(_xlpm.src,$I10&", "&$AC$3,_xlpm.a,KWANTI(_xlpm.src,($O$6&", "&$AD$3)),_xlpm.c,KWMIN(_xlpm.src,"Critical Wounds"),MIN(_xlpm.a,IF(ISNUMBER(_xlpm.c),MEDIAN(2,6,_xlpm.c),6))))} -> 6 | AO10: {=IF($C10="","",IF($AA10,0,_xlfn.LET(_xlpm.src,$I10&", "&$AC$3,_xlpm.stat,$F$3="Yes",IF(KW(_xlpm.src,"Snap Shooting")=TRUE,IF(_xlpm.stat,4,6),_xlfn.LET(_xlpm.psy,$AM10,_xlpm.hv,$AG10*_xlpm.stat,_xlpm.dmg,-($I$3="Yes"),_xlpm.am,$AS10,_xlpm.tm,$AI$3,_xlpm.mods,IF(_xlpm.psy,MAX(0,_xlpm.hv)+MAX(0,_xlpm.am)+MAX(0,_xlpm.tm),_xlpm.hv+_xlpm.dmg+_xlpm.am+_xlpm.tm),_xlpm.cov,AND(OR($G$3="Yes",$AB$3),NOT($AL10),NOT(_xlpm.psy)),_xlpm.bs,MIN(6,MAX(2,$E10+IF(_xlpm.psy,MIN(0,$BB10),$BB10+_xlpm.cov))),MEDIAN(2,6,_xlpm.bs-MAX(-1,MIN(1,_xlpm.mods))))))))} -> 3 | AP10: =IF($C10="","",_xlfn.LET(_xlpm.s,MAX(1,$F10+$BA10),_xlpm.t,MAX(1,N($J$6)+$AF$3),_xlpm.base,7-(1+(_xlpm.s>=2*_xlpm.t)+(_xlpm.s>_xlpm.t)+(_xlpm.s>=_xlpm.t)+(_xlpm.s>_xlpm.t/2)),MEDIAN(2,6,_xlpm.base-MAX(-1,MIN(1,$AT10+$AJ$3))))) -> 5 | AQ10: =IF($C10="","",_xlfn.LET(_xlpm.ap,MIN(0,$G10+$AU10+$AK$3),_xlpm.arm,$L$6-_xlpm.ap-$AG$3-$BD10,_xlpm.inv,IF(ISNUMBER($M$6),$M$6,7),MEDIAN(2,7,MIN(_xlpm.arm,_xlpm.inv)))) -> 5 | AR10: =IF(OR($C10="",N($K$6)<=0),"",ROUNDUP($K$6/MIN($V10,$K$6),0)/(($AA$3-1)/6)) -> 9 | AS10: {=IF($C10="","",KWSUM(($I10&", "&$AC$3),"Hit Modifier"))} -> 0 | AT10: {=IF($C10="","",KWSUM(($I10&", "&$AC$3),"Wound Modifier"))} -> 0 | AU10: {=IF($C10="","",KWSUM(($I10&", "&$AC$3),"AP Modifier"))} -> 0 | AV10: {=IF($C10="","",KWSUM(($I10&", "&$AC$3),"Damage Modifier"))} -> 0 | AW10: {=IF($C10="","",_xlfn.LET(_xlpm.src,$I10&", "&$AC$3,IF(KW(_xlpm.src,"Snap Shooting")=TRUE,0,_xlfn.LET(_xlpm.full,ISNUMBER(_xlfn.XMATCH("Reroll Hits",TRIM(_xlfn.TEXTSPLIT(_xlpm.src,",")))),_xlpm.r,KW(_xlpm.src,"Reroll Hits"),IF(_xlpm.full,2,IF(N(_xlpm.r)>=1,1,0))))))} -> 0 | AX10: {=IF($C10="","",_xlfn.LET(_xlpm.src,$I10&", "&$AC$3,_xlpm.full,OR($AE10,ISNUMBER(_xlfn.XMATCH("Reroll Wounds",TRIM(_xlfn.TEXTSPLIT(_xlpm.src,","))))),_xlpm.r,KW(_xlpm.src,"Reroll Wounds"),IF(_xlpm.full,2,IF(N(_xlpm.r)>=1,1,0))))} -> 0 | AY10: =IF($C10="","",IF($AA10,0,_xlfn.LET(_xlpm.pc,(7-$BC10)/6,_xlpm.p,MAX((7-$AO10)/6,_xlpm.pc),IF($AW10=2,_xlpm.pc+(1-_xlpm.p)*_xlpm.pc,IF($AW10=1,_xlpm.pc+_xlpm.pc/6,_xlpm.pc))))) -> 0.16666667 | AZ10: {=IF($C10="","",KWSUM($I10&", "&$AC$3,"Attacks Modifier"))} -> 0 | BA10: {=IF($C10="","",KWSUM($I10&", "&$AC$3,"Strength Modifier"))} -> 0 | BB10: {=IF($C10="","",KWSUM($I10&", "&$AC$3,"BS Modifier"))} -> 0 | BC10: {=IF($C10="","",_xlfn.LET(_xlpm.src,$I10&", "&$AC$3,_xlpm.c,KWMIN(_xlpm.src,"Critical Hits"),IF(KW(_xlpm.src,"Snap Shooting")=TRUE,6,IF(ISNUMBER(_xlpm.c),MEDIAN(2,6,_xlpm.c),6))))} -> 6 | BD10: {=IF($C10="","",KWSUM($I10&", "&$AC$3,"Save Modifier"))} -> 0 | BF10: Tallyman | BH10: Lord of Poxes (DeathGuard)
A11: TRUE | B11: 1 | C11: Plasma Pistol - Standard | D11: 1 | E11: 3 | F11: 7 | G11: -2 | H11: 1 | P11: {=IF(OR($C11="",NOT($A11)),"",N($B11)*(MAX(1,DICEAVG($D11)+$AZ11)+$AH11*($E$3="Yes")+($AI11+$AJ11)*INT($H$3/5)))} -> 1 | Q11: =IF(OR($C11="",NOT($A11)),"",IF($AA11,$P11,_xlfn.LET(_xlpm.p,MAX((7-$AO11)/6,(7-$BC11)/6),_xlpm.ph,IF($AW11=2,_xlpm.p+(1-_xlpm.p)*_xlpm.p,IF($AW11=1,_xlpm.p+_xlpm.p/6,_xlpm.p)),$P11*_xlpm.ph+$P11*$AY11*$AC11))) -> 0.66666667 | R11: =IF(OR($C11="",NOT($A11)),"",IF(AND($AB11,NOT($AA11)),$P11*$AY11,0)) -> 0 | S11: =IF(OR($C11="",NOT($A11)),"",_xlfn.LET(_xlpm.n,$Q11-$R11,_xlpm.pW,(7-$AP11)/6,_xlpm.pC,(7-$AN11)/6,_xlpm.pT,MAX(_xlpm.pW,_xlpm.pC),_xlpm.rr,$AX11,_xlpm.n*IF(_xlpm.rr=2,1-(1-_xlpm.pT)^2,IF(_xlpm.rr=1,_xlpm.pT+_xlpm.pT/6,_xlpm.pT))+$R11)) -> 0.22222222 | T11: =IF(OR($C11="",NOT($A11)),"",IF($AD11,_xlfn.LET(_xlpm.n,$Q11-$R11,_xlpm.pW,(7-$AP11)/6,_xlpm.pC,(7-$AN11)/6,_xlpm.pT,MAX(_xlpm.pW,_xlpm.pC),_xlpm.rr,$AX11,_xlpm.n*IF(_xlpm.rr=2,_xlpm.pC+(1-_xlpm.pT)*_xlpm.pC,IF(_xlpm.rr=1,_xlpm.pC+_xlpm.pC/6,_xlpm.pC))),0)) -> 0 | U11: =IF(OR($C11="",NOT($A11)),"",($S11-$T11)*($AQ11-1)/6) -> 0.11111111 | V11: {=IF(OR($C11="",NOT($A11)),"",MAX(1,DICEAVG($H11)+$AK11*($E$3="Yes")+$AV11+$AH$3))} -> 1 | W11: =IF(OR($C11="",NOT($A11)),"",($U11+$T11)*IF(N($K$6)>0,MIN($V11,$K$6),$V11)*($AA$3-1)/6) -> 0.11111111 | X11: =IF(OR($C11="",NOT($A11),$AR11=""),"",MIN($H$3,($U11+$T11)/$AR11)) -> 0.0065359477 | Y11: =IF(OR($C11="",NOT($A11)),"",TEXT($W11,"0.00")&" dmg"&IF($X11="","",", "&TEXT($X11,"0.00")&" kills")) -> 0.11 dmg, 0.01 kills | AA11: {=IF($C11="","",KW(($I11&", "&$AC$3),"Torrent")=TRUE)} -> FALSE | AB11: {=IF($C11="","",KW(($I11&", "&$AC$3),"Lethal Hits")=TRUE)} -> FALSE | AC11: {=IF($C11="","",N(KW(($I11&", "&$AC$3),"Sustained Hits")))} -> 0 | AD11: {=IF($C11="","",KW(($I11&", "&$AC$3),"Devastating Wounds")=TRUE)} -> FALSE | AE11: {=IF($C11="","",KW(($I11&", "&$AC$3),"Twin-Linked")=TRUE)} -> FALSE | AF11: {=IF($C11="","",KW(($I11&", "&$AC$3),"Lance")=TRUE)} -> FALSE | AG11: {=IF($C11="","",KW(($I11&", "&$AC$3),"Heavy")=TRUE)} -> FALSE | AH11: {=IF($C11="","",N(KW(($I11&", "&$AC$3),"Rapid Fire")))} -> 0 | AI11: {=IF($C11="","",N(KW(($I11&", "&$AC$3),"Blast")))} -> 0 | AJ11: {=IF($C11="","",N(KW(($I11&", "&$AC$3),"Cleave")))} -> 0 | AK11: {=IF($C11="","",N(KW(($I11&", "&$AC$3),"Melta")))} -> 0 | AL11: {=IF($C11="","",KW(($I11&", "&$AC$3),"Ignores Cover")=TRUE)} -> FALSE | AM11: {=IF($C11="","",KW(($I11&", "&$AC$3),"Psychic")=TRUE)} -> FALSE | AN11: {=IF($C11="","",_xlfn.LET(_xlpm.src,$I11&", "&$AC$3,_xlpm.a,KWANTI(_xlpm.src,($O$6&", "&$AD$3)),_xlpm.c,KWMIN(_xlpm.src,"Critical Wounds"),MIN(_xlpm.a,IF(ISNUMBER(_xlpm.c),MEDIAN(2,6,_xlpm.c),6))))} -> 6 | AO11: {=IF($C11="","",IF($AA11,0,_xlfn.LET(_xlpm.src,$I11&", "&$AC$3,_xlpm.stat,$F$3="Yes",IF(KW(_xlpm.src,"Snap Shooting")=TRUE,IF(_xlpm.stat,4,6),_xlfn.LET(_xlpm.psy,$AM11,_xlpm.hv,$AG11*_xlpm.stat,_xlpm.dmg,-($I$3="Yes"),_xlpm.am,$AS11,_xlpm.tm,$AI$3,_xlpm.mods,IF(_xlpm.psy,MAX(0,_xlpm.hv)+MAX(0,_xlpm.am)+MAX(0,_xlpm.tm),_xlpm.hv+_xlpm.dmg+_xlpm.am+_xlpm.tm),_xlpm.cov,AND(OR($G$3="Yes",$AB$3),NOT($AL11),NOT(_xlpm.psy)),_xlpm.bs,MIN(6,MAX(2,$E11+IF(_xlpm.psy,MIN(0,$BB11),$BB11+_xlpm.cov))),MEDIAN(2,6,_xlpm.bs-MAX(-1,MIN(1,_xlpm.mods))))))))} -> 3 | AP11: =IF($C11="","",_xlfn.LET(_xlpm.s,MAX(1,$F11+$BA11),_xlpm.t,MAX(1,N($J$6)+$AF$3),_xlpm.base,7-(1+(_xlpm.s>=2*_xlpm.t)+(_xlpm.s>_xlpm.t)+(_xlpm.s>=_xlpm.t)+(_xlpm.s>_xlpm.t/2)),MEDIAN(2,6,_xlpm.base-MAX(-1,MIN(1,$AT11+$AJ$3))))) -> 5 | AQ11: =IF($C11="","",_xlfn.LET(_xlpm.ap,MIN(0,$G11+$AU11+$AK$3),_xlpm.arm,$L$6-_xlpm.ap-$AG$3-$BD11,_xlpm.inv,IF(ISNUMBER($M$6),$M$6,7),MEDIAN(2,7,MIN(_xlpm.arm,_xlpm.inv)))) -> 4 | AR11: =IF(OR($C11="",N($K$6)<=0),"",ROUNDUP($K$6/MIN($V11,$K$6),0)/(($AA$3-1)/6)) -> 17 | AS11: {=IF($C11="","",KWSUM(($I11&", "&$AC$3),"Hit Modifier"))} -> 0 | AT11: {=IF($C11="","",KWSUM(($I11&", "&$AC$3),"Wound Modifier"))} -> 0 | AU11: {=IF($C11="","",KWSUM(($I11&", "&$AC$3),"AP Modifier"))} -> 0 | AV11: {=IF($C11="","",KWSUM(($I11&", "&$AC$3),"Damage Modifier"))} -> 0 | AW11: {=IF($C11="","",_xlfn.LET(_xlpm.src,$I11&", "&$AC$3,IF(KW(_xlpm.src,"Snap Shooting")=TRUE,0,_xlfn.LET(_xlpm.full,ISNUMBER(_xlfn.XMATCH("Reroll Hits",TRIM(_xlfn.TEXTSPLIT(_xlpm.src,",")))),_xlpm.r,KW(_xlpm.src,"Reroll Hits"),IF(_xlpm.full,2,IF(N(_xlpm.r)>=1,1,0))))))} -> 0 | AX11: {=IF($C11="","",_xlfn.LET(_xlpm.src,$I11&", "&$AC$3,_xlpm.full,OR($AE11,ISNUMBER(_xlfn.XMATCH("Reroll Wounds",TRIM(_xlfn.TEXTSPLIT(_xlpm.src,","))))),_xlpm.r,KW(_xlpm.src,"Reroll Wounds"),IF(_xlpm.full,2,IF(N(_xlpm.r)>=1,1,0))))} -> 0 | AY11: =IF($C11="","",IF($AA11,0,_xlfn.LET(_xlpm.pc,(7-$BC11)/6,_xlpm.p,MAX((7-$AO11)/6,_xlpm.pc),IF($AW11=2,_xlpm.pc+(1-_xlpm.p)*_xlpm.pc,IF($AW11=1,_xlpm.pc+_xlpm.pc/6,_xlpm.pc))))) -> 0.16666667 | AZ11: {=IF($C11="","",KWSUM($I11&", "&$AC$3,"Attacks Modifier"))} -> 0 | BA11: {=IF($C11="","",KWSUM($I11&", "&$AC$3,"Strength Modifier"))} -> 0 | BB11: {=IF($C11="","",KWSUM($I11&", "&$AC$3,"BS Modifier"))} -> 0 | BC11: {=IF($C11="","",_xlfn.LET(_xlpm.src,$I11&", "&$AC$3,_xlpm.c,KWMIN(_xlpm.src,"Critical Hits"),IF(KW(_xlpm.src,"Snap Shooting")=TRUE,6,IF(ISNUMBER(_xlpm.c),MEDIAN(2,6,_xlpm.c),6))))} -> 6 | BD11: {=IF($C11="","",KWSUM($I11&", "&$AC$3,"Save Modifier"))} -> 0 | BF11: Plague Marines (Meele) | BH11: Tallyman (DeathGuard)
A12: TRUE | B12: 1 | C12: Plasma Pistol Supercharged | D12: 1 | E12: 3 | F12: 8 | G12: -3 | H12: 2 | P12: {=IF(OR($C12="",NOT($A12)),"",N($B12)*(MAX(1,DICEAVG($D12)+$AZ12)+$AH12*($E$3="Yes")+($AI12+$AJ12)*INT($H$3/5)))} -> 1 | Q12: =IF(OR($C12="",NOT($A12)),"",IF($AA12,$P12,_xlfn.LET(_xlpm.p,MAX((7-$AO12)/6,(7-$BC12)/6),_xlpm.ph,IF($AW12=2,_xlpm.p+(1-_xlpm.p)*_xlpm.p,IF($AW12=1,_xlpm.p+_xlpm.p/6,_xlpm.p)),$P12*_xlpm.ph+$P12*$AY12*$AC12))) -> 0.66666667 | R12: =IF(OR($C12="",NOT($A12)),"",IF(AND($AB12,NOT($AA12)),$P12*$AY12,0)) -> 0 | S12: =IF(OR($C12="",NOT($A12)),"",_xlfn.LET(_xlpm.n,$Q12-$R12,_xlpm.pW,(7-$AP12)/6,_xlpm.pC,(7-$AN12)/6,_xlpm.pT,MAX(_xlpm.pW,_xlpm.pC),_xlpm.rr,$AX12,_xlpm.n*IF(_xlpm.rr=2,1-(1-_xlpm.pT)^2,IF(_xlpm.rr=1,_xlpm.pT+_xlpm.pT/6,_xlpm.pT))+$R12)) -> 0.22222222 | T12: =IF(OR($C12="",NOT($A12)),"",IF($AD12,_xlfn.LET(_xlpm.n,$Q12-$R12,_xlpm.pW,(7-$AP12)/6,_xlpm.pC,(7-$AN12)/6,_xlpm.pT,MAX(_xlpm.pW,_xlpm.pC),_xlpm.rr,$AX12,_xlpm.n*IF(_xlpm.rr=2,_xlpm.pC+(1-_xlpm.pT)*_xlpm.pC,IF(_xlpm.rr=1,_xlpm.pC+_xlpm.pC/6,_xlpm.pC))),0)) -> 0 | U12: =IF(OR($C12="",NOT($A12)),"",($S12-$T12)*($AQ12-1)/6) -> 0.14814815 | V12: {=IF(OR($C12="",NOT($A12)),"",MAX(1,DICEAVG($H12)+$AK12*($E$3="Yes")+$AV12+$AH$3))} -> 2 | W12: =IF(OR($C12="",NOT($A12)),"",($U12+$T12)*IF(N($K$6)>0,MIN($V12,$K$6),$V12)*($AA$3-1)/6) -> 0.2962963 | X12: =IF(OR($C12="",NOT($A12),$AR12=""),"",MIN($H$3,($U12+$T12)/$AR12)) -> 0.016460905 | Y12: =IF(OR($C12="",NOT($A12)),"",TEXT($W12,"0.00")&" dmg"&IF($X12="","",", "&TEXT($X12,"0.00")&" kills")) -> 0.30 dmg, 0.02 kills | AA12: {=IF($C12="","",KW(($I12&", "&$AC$3),"Torrent")=TRUE)} -> FALSE | AB12: {=IF($C12="","",KW(($I12&", "&$AC$3),"Lethal Hits")=TRUE)} -> FALSE | AC12: {=IF($C12="","",N(KW(($I12&", "&$AC$3),"Sustained Hits")))} -> 0 | AD12: {=IF($C12="","",KW(($I12&", "&$AC$3),"Devastating Wounds")=TRUE)} -> FALSE | AE12: {=IF($C12="","",KW(($I12&", "&$AC$3),"Twin-Linked")=TRUE)} -> FALSE | AF12: {=IF($C12="","",KW(($I12&", "&$AC$3),"Lance")=TRUE)} -> FALSE | AG12: {=IF($C12="","",KW(($I12&", "&$AC$3),"Heavy")=TRUE)} -> FALSE | AH12: {=IF($C12="","",N(KW(($I12&", "&$AC$3),"Rapid Fire")))} -> 0 | AI12: {=IF($C12="","",N(KW(($I12&", "&$AC$3),"Blast")))} -> 0 | AJ12: {=IF($C12="","",N(KW(($I12&", "&$AC$3),"Cleave")))} -> 0 | AK12: {=IF($C12="","",N(KW(($I12&", "&$AC$3),"Melta")))} -> 0 | AL12: {=IF($C12="","",KW(($I12&", "&$AC$3),"Ignores Cover")=TRUE)} -> FALSE | AM12: {=IF($C12="","",KW(($I12&", "&$AC$3),"Psychic")=TRUE)} -> FALSE | AN12: {=IF($C12="","",_xlfn.LET(_xlpm.src,$I12&", "&$AC$3,_xlpm.a,KWANTI(_xlpm.src,($O$6&", "&$AD$3)),_xlpm.c,KWMIN(_xlpm.src,"Critical Wounds"),MIN(_xlpm.a,IF(ISNUMBER(_xlpm.c),MEDIAN(2,6,_xlpm.c),6))))} -> 6 | AO12: {=IF($C12="","",IF($AA12,0,_xlfn.LET(_xlpm.src,$I12&", "&$AC$3,_xlpm.stat,$F$3="Yes",IF(KW(_xlpm.src,"Snap Shooting")=TRUE,IF(_xlpm.stat,4,6),_xlfn.LET(_xlpm.psy,$AM12,_xlpm.hv,$AG12*_xlpm.stat,_xlpm.dmg,-($I$3="Yes"),_xlpm.am,$AS12,_xlpm.tm,$AI$3,_xlpm.mods,IF(_xlpm.psy,MAX(0,_xlpm.hv)+MAX(0,_xlpm.am)+MAX(0,_xlpm.tm),_xlpm.hv+_xlpm.dmg+_xlpm.am+_xlpm.tm),_xlpm.cov,AND(OR($G$3="Yes",$AB$3),NOT($AL12),NOT(_xlpm.psy)),_xlpm.bs,MIN(6,MAX(2,$E12+IF(_xlpm.psy,MIN(0,$BB12),$BB12+_xlpm.cov))),MEDIAN(2,6,_xlpm.bs-MAX(-1,MIN(1,_xlpm.mods))))))))} -> 3 | AP12: =IF($C12="","",_xlfn.LET(_xlpm.s,MAX(1,$F12+$BA12),_xlpm.t,MAX(1,N($J$6)+$AF$3),_xlpm.base,7-(1+(_xlpm.s>=2*_xlpm.t)+(_xlpm.s>_xlpm.t)+(_xlpm.s>=_xlpm.t)+(_xlpm.s>_xlpm.t/2)),MEDIAN(2,6,_xlpm.base-MAX(-1,MIN(1,$AT12+$AJ$3))))) -> 5 | AQ12: =IF($C12="","",_xlfn.LET(_xlpm.ap,MIN(0,$G12+$AU12+$AK$3),_xlpm.arm,$L$6-_xlpm.ap-$AG$3-$BD12,_xlpm.inv,IF(ISNUMBER($M$6),$M$6,7),MEDIAN(2,7,MIN(_xlpm.arm,_xlpm.inv)))) -> 5 | AR12: =IF(OR($C12="",N($K$6)<=0),"",ROUNDUP($K$6/MIN($V12,$K$6),0)/(($AA$3-1)/6)) -> 9 | AS12: {=IF($C12="","",KWSUM(($I12&", "&$AC$3),"Hit Modifier"))} -> 0 | AT12: {=IF($C12="","",KWSUM(($I12&", "&$AC$3),"Wound Modifier"))} -> 0 | AU12: {=IF($C12="","",KWSUM(($I12&", "&$AC$3),"AP Modifier"))} -> 0 | AV12: {=IF($C12="","",KWSUM(($I12&", "&$AC$3),"Damage Modifier"))} -> 0 | AW12: {=IF($C12="","",_xlfn.LET(_xlpm.src,$I12&", "&$AC$3,IF(KW(_xlpm.src,"Snap Shooting")=TRUE,0,_xlfn.LET(_xlpm.full,ISNUMBER(_xlfn.XMATCH("Reroll Hits",TRIM(_xlfn.TEXTSPLIT(_xlpm.src,",")))),_xlpm.r,KW(_xlpm.src,"Reroll Hits"),IF(_xlpm.full,2,IF(N(_xlpm.r)>=1,1,0))))))} -> 0 | AX12: {=IF($C12="","",_xlfn.LET(_xlpm.src,$I12&", "&$AC$3,_xlpm.full,OR($AE12,ISNUMBER(_xlfn.XMATCH("Reroll Wounds",TRIM(_xlfn.TEXTSPLIT(_xlpm.src,","))))),_xlpm.r,KW(_xlpm.src,"Reroll Wounds"),IF(_xlpm.full,2,IF(N(_xlpm.r)>=1,1,0))))} -> 0 | AY12: =IF($C12="","",IF($AA12,0,_xlfn.LET(_xlpm.pc,(7-$BC12)/6,_xlpm.p,MAX((7-$AO12)/6,_xlpm.pc),IF($AW12=2,_xlpm.pc+(1-_xlpm.p)*_xlpm.pc,IF($AW12=1,_xlpm.pc+_xlpm.pc/6,_xlpm.pc))))) -> 0.16666667 | AZ12: {=IF($C12="","",KWSUM($I12&", "&$AC$3,"Attacks Modifier"))} -> 0 | BA12: {=IF($C12="","",KWSUM($I12&", "&$AC$3,"Strength Modifier"))} -> 0 | BB12: {=IF($C12="","",KWSUM($I12&", "&$AC$3,"BS Modifier"))} -> 0 | BC12: {=IF($C12="","",_xlfn.LET(_xlpm.src,$I12&", "&$AC$3,_xlpm.c,KWMIN(_xlpm.src,"Critical Hits"),IF(KW(_xlpm.src,"Snap Shooting")=TRUE,6,IF(ISNUMBER(_xlpm.c),MEDIAN(2,6,_xlpm.c),6))))} -> 6 | BD12: {=IF($C12="","",KWSUM($I12&", "&$AC$3,"Save Modifier"))} -> 0 | BH12: Typhus (DeathGuard)
